Workbook

Sheet Kangatang

Sheet Sheet1
A1: THÁNG 02/2026
A2: TÍNH TOÁN TIÊU CHUẨN, SỬ DỤNG ĐIỆN NƯỚC
B4: I. BẢNG TÍNH TỔN HAO VÀ SỬ DỤNG THỰC TẾ
B5: 1. Bảng tính các vị trí có công tơ tại trạm, không có tổn hao
C6: Số đầu kỳ | D6: Số cuối kỳ | E6: Sử dụng
B7: Tiểu đoàn 18 | C7: 95440 | D7: 99460 | E7: =D7-C7 -> 4020
B8: Tổng | E8: =SUM(E7:E7) -> 4020
B9: Số sử dụng toàn đơn vị theo công tơ tổng điện lực | H9: 45960
B10: Số sử dụng sau khi trừ các vị trí không có tổn hao | G10: A= | H10: =H9-E8 -> 41940
A12: Đơn vị | B12: Chi tiết | C12: Nhà ở | E12: Nhà làm việc | G12: Số sử dụng | H12: Số tổn hao | I12: Số sử dụng thực tế bao gồm cả tổn hao
C13: Số đầu kỳ | D13: Số cuối kỳ | E13: Số đầu kỳ | F13: Số cuối kỳ
C14: 3 | D14: 4 | E14: 5 | F14: 6 | G14: 7=4+6-3-5 | H14: 8 | I14: 9
A15: Chỉ huy f | B15: Chỉ huy f +N.khách | C15: 90885 | D15: 98320 | G15: =D15+F15-C15-E15 -> 7435 | H15: =G15*$D$157/$G$153 -> 324.12959 | I15: =G15+H15 -> 7759.1296
B16: Sư đoàn trưởng | E16: 814 | F16: 815 | G16: =D16+F16-C16-E16 -> 1 | H16: =G16*$D$157/$G$153 -> 0.043595103 | I16: =G16+H16 -> 1.0435951
B17: Phó Sư đoàn trưởng | E17: 180 | F17: 180 | G17: =D17+F17-C17-E17 -> 0 | H17: =G17*$D$157/$G$153 -> 0 | I17: =G17+H17 -> 0
B18: Phó Sư đoàn trưởng-TMT | E18: 526 | F18: 527 | G18: =D18+F18-C18-E18 -> 1 | H18: =G18*$D$157/$G$153 -> 0.043595103 | I18: =G18+H18 -> 1.0435951
B19: Chính uỷ | E19: 1589 | F19: 1589 | G19: =D19+F19-C19-E19 -> 0 | H19: =G19*$D$157/$G$153 -> 0 | I19: =G19+H19 -> 0
B20: Phó Chỉnh uỷ | E20: 479 | F20: 479 | G20: =D20+F20-C20-E20 -> 0 | H20: =G20*$D$157/$G$153 -> 0 | I20: =G20+H20 -> 0
H21: =G21*$D$157/$G$153 -> 0
A22: CH. PTM | B22: TMP Trường | C22: 13223 | D22: 13322 | E22: 87 | F22: 87 | G22: =D22+F22-C22-E22 -> 99 | H22: =G22*$D$157/$G$153 -> 4.3159152 | I22: =G22+H22 -> 103.31592
B23: TMP Hưng | C23: 14106 | D23: 14231 | E23: 65 | F23: 65 | G23: =D23+F23-C23-E23 -> 125 | H23: =G23*$D$157/$G$153 -> 5.4493879 | I23: =G23+H23 -> 130.44939
B24: TMP Hiếu | C24: 12774 | D24: 12875 | G24: =D24+F24-C24-E24 -> 101 | H24: =G24*$D$157/$G$153 -> 4.4031054 | I24: =G24+H24 -> 105.40311
A25: Ban Q.lực | B25: ĐH TB Q. Lực | C25: 11709 | D25: 11807 | E25: 672 | F25: 683 | G25: =D25+F25-C25-E25 -> 109 | H25: =G25*$D$157/$G$153 -> 4.7518662 | I25: =G25+H25 -> 113.75187
B26: Thành; Thế; Huy | C26: 26593 | D26: 26985 | E26: 19284 | F26: 19412 | G26: =D26+F26-C26-E26 -> 520 | H26: =G26*$D$157/$G$153 -> 22.669454 | I26: =G26+H26 -> 542.66945
B27: Quỳnh; Chuyên; Tú | C27: 12547 | D27: 12806 | G27: =D27+F27-C27-E27 -> 259 | H27: =G27*$D$157/$G$153 -> 11.291132 | I27: =G27+H27 -> 270.29113
A28: Ban Tác huấn | B28: Trưởng ban + Qúy | C28: 10495 | D28: 10608 | E28: 423 | F28: 450 | G28: =D28+F28-C28-E28+(F29-E29) -> 486 | H28: =G28*$D$157/$G$153 -> 21.18722 | I28: =G28+H28 -> 507.18722 | K28: =L28+N28 -> 28.177068 | L28: =F28-E28 -> 27 | M28: =H153/G153 -> 0.043595103 | N28: =L28*M28 -> 1.1770678
B29: Tuấn, Nam,Công | C29: 9551 | D29: 9779 | E29: 21807 | F29: 22153 | G29: =D29-C29 -> 228 | H29: =G29*$D$157/$G$153 -> 9.9396835 | I29: =G29+H29 -> 237.93968 | K29: =L29+N29 -> 361.08391 | L29: =F29-E29 -> 346 | M29: =H153/G153 -> 0.043595103 | N29: =L29*M29 -> 15.083906
B30: Thiệp, Chung | C30: 10100 | D30: 10267 | G30: =D30+F30-C30-E30 -> 167 | H30: =G30*$D$157/$G$153 -> 7.2803822 | I30: =G30+H30 -> 174.28038 | K30: =F30-E30 -> 0
B31: Tuấn; Chiến sỹ | C31: 18454 | D31: 18587 | G31: =D31+F31-C31-E31 -> 133 | H31: =G31*$D$157/$G$153 -> 5.7981487 | I31: =G31+H31 -> 138.79815 | K31: =F31-E31 -> 0
B32: Bản đồ | E32: 8041 | F32: 8149 | G32: =D32+F32-C32-E32 -> 108 | H32: =G32*$D$157/$G$153 -> 4.7082711 | I32: =G32+H32 -> 112.70827 | K32: =I32 -> 112.70827
A33: B. T.sát | B33: TB + Ngọc | C33: 20577 | D33: 20762 | E33: 1306 | F33: 1322 | G33: =D33+F33-C33-E33 -> 201 | H33: =G33*$D$157/$G$153 -> 8.7626157 | I33: =G33+H33 -> 209.76262 | K33: =SUM(K28:K32) -> 501.96924
B34: TL Dũng | C34: 8401 | D34: 8484 | G34: =D34+F34-C34-E34 -> 83 | H34: =G34*$D$157/$G$153 -> 3.6183936 | I34: =G34+H34 -> 86.618394
A35: B. C.Binh | B35: TB + Tùng + Linh | C35: 17220 | D35: 17428 | E35: 808 | F35: 827 | G35: =D35+F35-C35-E35 -> 227 | H35: =G35*$D$157/$G$153 -> 9.8960884 | I35: =G35+H35 -> 236.89609
B36: Phiêu; Hưng | C36: 6387 | D36: 6466 | G36: =D36+F36-C36-E36 -> 79 | H36: =G36*$D$157/$G$153 -> 3.4440131 | I36: =G36+H36 -> 82.444013
A37: B. P.Binh | B37: TB + Mạnh | C37: 18984 | D37: 19205 | E37: 1182 | F37: 1195 | G37: =D37+F37-C37-E37 -> 234 | H37: =G37*$D$157/$G$153 -> 10.201254 | I37: =G37+H37 -> 244.20125
B38: TL Anh; Diến | C38: 1931 | D38: 2015 | G38: =D38+F38-C38-E38 -> 84 | H38: =G38*$D$157/$G$153 -> 3.6619887 | I38: =G38+H38 -> 87.661989
A39: B. P.Không | B39: TB + Cường | C39: 25368 | D39: 25483 | E39: 1209 | F39: 1222 | G39: =D39+F39-C39-E39 -> 128 | H39: =G39*$D$157/$G$153 -> 5.5801732 | I39: =G39+H39 -> 133.58017
B40: Nguyên PB; Công TH | C40: 12447 | D40: 12668 | G40: =D40+F40-C40-E40 -> 221 | H40: =G40*$D$157/$G$153 -> 9.6345178 | I40: =G40+H40 -> 230.63452
A41: B. T.Tin | B41: TB + Khôi | C41: 23538 | D41: 23624 | E41: 1005 | F41: 1014 | G41: =D41+F41-C41-E41 -> 95 | H41: =G41*$D$157/$G$153 -> 4.1415348 | I41: =G41+H41 -> 99.141535
B42: Trạm cơ công | C42: 4704 | D42: 5057 | G42: =D42+F42-C42-E42 -> 353 | H42: =G42*$D$157/$G$153 -> 15.389071 | I42: =G42+H42 -> 368.38907
...

Sheet Sheet1 (2)
A2: TÍNH TOÁN TIÊU CHUẨN, SỬ DỤNG ĐIỆN NƯỚC THÁNG 02/2026
D4: III. BẢNG TÍNH SỬ DỤNG ĐIỆN
B6: STT | C6: Đơn vị | E6: Tiêu chuẩn sinh hoạt làm việc | J6: Tiêu chuẩn điện bơm nước (kW) | K6: Phần trừ tiêu chuẩn | N6: Tiêu chuẩn còn lại | O6: Sử dụng | R6: Số thâm điện | S6: Đơn giá (đồng) | T6: Thành tiền (đồng) | U6: Tổng | V6: Người phụ trách | W6: Ký nhận
E7: 3// 4// | F7: 1// 2// | G7: Cấp úy | H7: HSQ-CS | I7: Tổng (kW) | K7: Tiết kiệm của Bộ 5% | L7: Công cộng chung của Sư đoàn 10 % | M7: Điện nhà ăn + bếp | O7: Số sử dụng thực tế bao gồm cả tổn hao | P7: Điện bơm nước | Q7: Tổng cộng
I8: (1) | J8: (2) | K8: (3)=(1+2)*5% | L8: (4)=(1+2)*10% | M8: (5) | N8: (6)=(1+2-3-4-5) | P8: =Sheet1!D165 -> 2025.186 | S8: 2336.4
B9: I | C9: Phòng Tham mưu
B10: 1 | C10: TMP Trường | E10: 1 | I10: =E10*115+F10*38+G10*28+H10*11 -> 115 | J10: =SUM(E10:H10)*6.3 -> 6.3 | K10: =(I10+J10)*5% -> 6.065 | L10: =(I10+J10)*10% -> 12.13 | N10: =I10+J10-K10-L10-M10 -> 103.105 | O10: =Sheet1!I22 -> 103.31592 | P10: =SUM(E10:H10)*$P$8/$P$92 -> 10.547844 | Q10: =SUM(O10:P10) -> 113.86376 | R10: =Q10-N10 -> 10.758759 | S10: =$S$8 -> 2336.4 | T10: =R10*S10 -> 25136.765 | U10: =T10 -> 25136.765 | V10: Nguyễn Văn Trường
B11: 2 | C11: TMP Hưng | E11: 1 | I11: =E11*115+F11*38+G11*28+H11*11 -> 115 | J11: =SUM(E11:H11)*6.3 -> 6.3 | K11: =(I11+J11)*5% -> 6.065 | L11: =(I11+J11)*10% -> 12.13 | N11: =I11+J11-K11-L11-M11 -> 103.105 | O11: =Sheet1!I23 -> 130.44939 | P11: =SUM(E11:H11)*$P$8/$P$92 -> 10.547844 | Q11: =SUM(O11:P11) -> 140.99723 | R11: =Q11-N11 -> 37.892232 | S11: =$S$8 -> 2336.4 | T11: =R11*S11 -> 88531.41 | U11: =T11 -> 88531.41 | V11: Tống Xuân Hưng
B12: 3 | C12: TMP Hiếu | E12: 1 | I12: =E12*115+F12*38+G12*28+H12*11 -> 115 | J12: =SUM(E12:H12)*6.3 -> 6.3 | K12: =(I12+J12)*5% -> 6.065 | L12: =(I12+J12)*10% -> 12.13 | N12: =I12+J12-K12-L12-M12 -> 103.105 | O12: =Sheet1!I24 -> 105.40311 | P12: =SUM(E12:H12)*$P$8/$P$92 -> 10.547844 | Q12: =SUM(O12:P12) -> 115.95095 | R12: =Q12-N12 -> 12.845949 | S12: =$S$8 -> 2336.4 | T12: 82704 | U12: 82704 | V12: Nguyễn Trung Hiếu
B13: 4 | C13: Ban Quân lực | D13: TB Q. Lực | F13: 1 | H13: 1 | I13: =E13*115+F13*38+G13*28+H13*11 -> 49 | J13: =SUM(E13:H13)*6.3 -> 12.6 | K13: =(I13+J13)*5% -> 3.08 | L13: =(I13+J13)*10% -> 6.16 | M13: =SUM(E13:H13)*2 -> 4 | N13: =I13+J13-K13-L13-M13 -> 48.36 | O13: =Sheet1!I25 -> 113.75187 | P13: =SUM(E13:H13)*$P$8/$P$92 -> 21.095688 | Q13: =SUM(O13:P13) -> 134.84755 | R13: =Q13-N13 -> 86.487554 | S13: =$S$8 -> 2336.4 | T13: =R13*S13 -> 202069.52 | U13: =T13+T14+T15 -> 1808168.8 | V13: Ngô Thế Biên | X13: =T13+T14+T15 -> 1808168.8
D14: Thành; Thế | F14: 2 | I14: =E14*115+F14*38+G14*28+H14*11 -> 76 | J14: =SUM(E14:H14)*6.3 -> 12.6 | K14: =(I14+J14)*5% -> 4.43 | L14: =(I14+J14)*10% -> 8.86 | M14: =SUM(E14:H14)*2 -> 4 | N14: =I14+J14-K14-L14-M14 -> 71.31 | O14: =Sheet1!I26 -> 542.66945 | P14: =SUM(E14:H14)*$P$8/$P$92 -> 21.095688 | Q14: =SUM(O14:P14) -> 563.76514 | R14: =Q14-N14 -> 492.45514 | S14: =$S$8 -> 2336.4 | T14: =R14*S14 -> 1150572.2
D15: Quỳnh; Tú | F15: 3 | I15: =E15*115+F15*38+G15*28+H15*11 -> 114 | J15: =SUM(E15:H15)*6.3 -> 18.9 | K15: =(I15+J15)*5% -> 6.645 | L15: =(I15+J15)*10% -> 13.29 | M15: =SUM(E15:H15)*2 -> 6 | N15: =I15+J15-K15-L15-M15 -> 106.965 | O15: =Sheet1!I27 -> 270.29113 | P15: =SUM(E15:H15)*$P$8/$P$92 -> 31.643532 | Q15: =SUM(O15:P15) -> 301.93466 | R15: =Q15-N15 -> 194.96966 | S15: =$S$8 -> 2336.4 | T15: =R15*S15 -> 455527.12
B16: 5 | C16: Ban Tác Huấn | D16: Trưởng ban + QUÝ | F16: 2 | I16: =E16*115+F16*38+G16*28+H16*11 -> 76 | J16: =SUM(E16:H16)*6.3 -> 12.6 | K16: =(I16+J16)*5% -> 4.43 | L16: =(I16+J16)*10% -> 8.86 | M16: =SUM(E16:H16)*2 -> 4 | N16: =I16+J16-K16-L16-M16 -> 71.31 | O16: =Sheet1!I28 -> 507.18722 | P16: =SUM(E16:H16)*$P$8/$P$92 -> 21.095688 | Q16: =SUM(O16:P16) -> 528.28291 | R16: =Q16-N16 -> 456.97291 | S16: =$S$8 -> 2336.4 | T16: =R16*S16 -> 1067671.5 | U16: =SUM(T16:T20) -> 2202739.6 | V16: Đàm Văn Khỏe (Điện nlv = 502 kW)
D17: Tuấn, Nam,Công | F17: 3 | I17: =E17*115+F17*38+G17*28+H17*11 -> 114 | J17: =SUM(E17:H17)*6.3 -> 18.9 | K17: =(I17+J17)*5% -> 6.645 | L17: =(I17+J17)*10% -> 13.29 | M17: =SUM(E17:H17)*2 -> 6 | N17: =I17+J17-K17-L17-M17 -> 106.965 | O17: =Sheet1!I29 -> 237.93968 | P17: =SUM(E17:H17)*$P$8/$P$92 -> 31.643532 | Q17: =SUM(O17:P17) -> 269.58322 | R17: =Q17-N17 -> 162.61822 | S17: =$S$8 -> 2336.4 | T17: =R17*S17 -> 379941.2 | X17: =Sheet1!K33 -> 501.96924
D18: Thiệp, Chung | F18: 2 | I18: =E18*115+F18*38+G18*28+H18*11 -> 76 | J18: =SUM(E18:H18)*6.3 -> 12.6 | K18: =(I18+J18)*5% -> 4.43 | L18: =(I18+J18)*10% -> 8.86 | M18: =SUM(E18:H18)*2 -> 4 | N18: =I18+J18-K18-L18-M18 -> 71.31 | O18: =Sheet1!I30 -> 174.28038 | P18: =SUM(E18:H18)*$P$8/$P$92 -> 21.095688 | Q18: =SUM(O18:P18) -> 195.37607 | R18: =Q18-N18 -> 124.06607 | S18: =$S$8 -> 2336.4 | T18: =R18*S18 -> 289867.97
D19: Tuấn, chiến sĩ | F19: 1 | H19: 1 | I19: =E19*115+F19*38+G19*28+H19*11 -> 49 | J19: =SUM(E19:H19)*6.3 -> 12.6 | K19: =(I19+J19)*5% -> 3.08 | L19: =(I19+J19)*10% -> 6.16 | M19: =SUM(E19:H19)*2 -> 4 | N19: =I19+J19-K19-L19-M19 -> 48.36 | O19: =Sheet1!I31 -> 138.79815 | P19: =SUM(E19:H19)*$P$8/$P$92 -> 21.095688 | Q19: =SUM(O19:P19) -> 159.89384 | R19: =Q19-N19 -> 111.53384 | S19: =$S$8 -> 2336.4 | T19: =R19*S19 -> 260587.66
D20: Bản đồ | F20: 1 | I20: =E20*115+F20*38+G20*28+H20*11 -> 38 | J20: =SUM(E20:H20)*6.3 -> 6.3 | K20: =(I20+J20)*5% -> 2.215 | L20: =(I20+J20)*10% -> 4.43 | M20: =SUM(E20:H20)*2 -> 2 | N20: =I20+J20-K20-L20-M20 -> 35.655 | O20: =Sheet1!I32 -> 112.70827 | P20: =SUM(E20:H20)*$P$8/$P$92 -> 10.547844 | Q20: =SUM(O20:P20) -> 123.25612 | R20: =Q20-N20 -> 87.601115 | S20: =$S$8 -> 2336.4 | T20: =R20*S20 -> 204671.25
B21: 6 | C21: Ban Trinh sát | D21: TB TS + Ngọc | F21: 2 | I21: =E21*115+F21*38+G21*28+H21*11 -> 76 | J21: =SUM(E21:H21)*6.3 -> 12.6 | K21: =(I21+J21)*5% -> 4.43 | L21: =(I21+J21)*10% -> 8.86 | M21: =SUM(E21:H21)*2 -> 4 | N21: =I21+J21-K21-L21-M21 -> 71.31 | O21: =Sheet1!I33 -> 209.76262 | P21: =SUM(E21:H21)*$P$8/$P$92 -> 21.095688 | Q21: =SUM(O21:P21) -> 230.8583 | R21: =Q21-N21 -> 159.5483 | S21: =$S$8 -> 2336.4 | T21: =R21*S21 -> 372768.66 | U21: =T21+T22 -> 516483.51 | V21: Trần Văn Ngọc
D22: TL Dũng | F22: 1 | I22: =E22*115+F22*38+G22*28+H22*11 -> 38 | J22: =SUM(E22:H22)*6.3 -> 6.3 | K22: =(I22+J22)*5% -> 2.215 | L22: =(I22+J22)*10% -> 4.43 | M22: =SUM(E22:H22)*2 -> 2 | N22: =I22+J22-K22-L22-M22 -> 35.655 | O22: =Sheet1!I34 -> 86.618394 | P22: =SUM(E22:H22)*$P$8/$P$92 -> 10.547844 | Q22: =SUM(O22:P22) -> 97.166238 | R22: =Q22-N22 -> 61.511238 | S22: =$S$8 -> 2336.4 | T22: =R22*S22 -> 143714.86
B23: 7 | C23: Ban Công binh | D23: TB + Tùng +Cường | F23: 2 | G23: 1 | I23: =E23*115+F23*38+G23*28+H23*11 -> 104 | J23: =SUM(E23:H23)*6.3 -> 18.9 | K23: =(I23+J23)*5% -> 6.145 | L23: =(I23+J23)*10% -> 12.29 | M23: =SUM(E23:H23)*2 -> 6 | N23: =I23+J23-K23-L23-M23 -> 98.465 | O23: =Sheet1!I35 -> 236.89609 | P23: =SUM(E23:H23)*$P$8/$P$92 -> 31.643532 | Q23: =SUM(O23:P23) -> 268.53962 | R23: =Q23-N23 -> 170.07462 | S23: =$S$8 -> 2336.4 | T23: =R23*S23 -> 397362.34 | U23: =T23+T24 -> 472663.82 | V23: Phạm Duy Hưng
D24: Hưng,Phiêu | F24: 2 | I24: =E24*115+F24*38+G24*28+H24*11 -> 76 | J24: =SUM(E24:H24)*6.3 -> 12.6 | K24: =(I24+J24)*5% -> 4.43 | L24: =(I24+J24)*10% -> 8.86 | M24: =SUM(E24:H24)*2 -> 4 | N24: =I24+J24-K24-L24-M24 -> 71.31 | O24: =Sheet1!I36 -> 82.444013 | P24: =SUM(E24:H24)*$P$8/$P$92 -> 21.095688 | Q24: =SUM(O24:P24) -> 103.5397 | R24: =Q24-N24 -> 32.229701 | S24: =$S$8 -> 2336.4 | T24: =R24*S24 -> 75301.474
B25: 8 | C25: Ban Pháo binh | D25: TB + Mạnh | F25: 2 | I25: =E25*115+F25*38+G25*28+H25*11 -> 76 | J25: =SUM(E25:H25)*6.3 -> 12.6 | K25: =(I25+J25)*5% -> 4.43 | L25: =(I25+J25)*10% -> 8.86 | M25: =SUM(E25:H25)*2 -> 4 | N25: =I25+J25-K25-L25-M25 -> 71.31 | O25: =Sheet1!I37 -> 244.20125 | P25: =SUM(E25:H25)*$P$8/$P$92 -> 21.095688 | Q25: =SUM(O25:P25) -> 265.29694 | R25: =Q25-N25 -> 193.98694 | S25: =$S$8 -> 2336.4 | T25: =R25*S25 -> 453231.09 | U25: =T25+T26 -> 540723.84 | V25: Nguyễn Anh Trung
D26: TL Anh; Diến | F26: 2 | I26: =E26*115+F26*38+G26*28+H26*11 -> 76 | J26: =SUM(E26:H26)*6.3 -> 12.6 | K26: =(I26+J26)*5% -> 4.43 | L26: =(I26+J26)*10% -> 8.86 | M26: =SUM(E26:H26)*2 -> 4 | N26: =I26+J26-K26-L26-M26 -> 71.31 | O26: =Sheet1!I38 -> 87.661989 | P26: =SUM(E26:H26)*$P$8/$P$92 -> 21.095688 | Q26: =SUM(O26:P26) -> 108.75768 | R26: =Q26-N26 -> 37.447677 | S26: =$S$8 -> 2336.4 | T26: =R26*S26 -> 87492.752
B27: 9 | C27: Ban Phòng không | D27: TB + Cường | F27: 2 | G27: 1 | I27: =E27*115+F27*38+G27*28+H27*11 -> 104 | J27: =SUM(E27:H27)*6.3 -> 18.9 | K27: =(I27+J27)*5% -> 6.145 | L27: =(I27+J27)*10% -> 12.29 | M27: =SUM(E27:H27)*2 -> 6 | N27: =I27+J27-K27-L27-M27 -> 98.465 | O27: =Sheet1!I39 -> 133.58017 | P27: =SUM(E27:H27)*$P$8/$P$92 -> 31.643532 | Q27: =SUM(O27:P27) -> 165.22371 | R27: =Q27-N27 -> 66.758705 | S27: =$S$8 -> 2336.4 | T27: =R27*S27 -> 155975.04 | U27: =T27+T28 -> 577508.81 | V27: Nguyễn Văn Cường
D28: Nguyên,Đạt | F28: 2 | I28: =E28*115+F28*38+G28*28+H28*11 -> 76 | J28: =SUM(E28:H28)*6.3 -> 12.6 | K28: =(I28+J28)*5% -> 4.43 | L28: =(I28+J28)*10% -> 8.86 | M28: =SUM(E28:H28)*2 -> 4 | N28: =I28+J28-K28-L28-M28 -> 71.31 | O28: =Sheet1!I40 -> 230.63452 | P28: =SUM(E28:H28)*$P$8/$P$92 -> 21.095688 | Q28: =SUM(O28:P28) -> 251.73021 | R28: =Q28-N28 -> 180.42021 | S28: =$S$8 -> 2336.4 | T28: =R28*S28 -> 421533.77
B29: 10 | C29: Ban thông tin | D29: TB + Khôi | F29: 2 | I29: =E29*115+F29*38+G29*28+H29*11 -> 76 | J29: =SUM(E29:H29)*6.3 -> 12.6 | K29: =(I29+J29)*5% -> 4.43 | L29: =(I29+J29)*10% -> 8.86 | M29: =SUM(E29:H29)*2 -> 4 | N29: =I29+J29-K29-L29-M29 -> 71.31 | O29: =Sheet1!I41 -> 99.141535 | P29: =SUM(E29:H29)*$P$8/$P$92 -> 21.095688 | Q29: =SUM(O29:P29) -> 120.23722 | R29: =Q29-N29 -> 48.927223 | S29: =$S$8 -> 2336.4 | T29: =R29*S29 -> 114313.56 | U29: =T29+T30 -> 713697.77 | V29: Lương Tuấn Hùng
D30: TL Khương; Nghĩa | F30: 3 | I30: =E30*115+F30*38+G30*28+H30*11 -> 114 | J30: =SUM(E30:H30)*6.3 -> 18.9 | K30: =(I30+J30)*5% -> 6.645 | L30: =(I30+J30)*10% -> 13.29 | M30: =SUM(E30:H30)*2 -> 6 | N30: =I30+J30-K30-L30-M30 -> 106.965 | O30: =Sheet1!I43 -> 331.86324 | P30: =SUM(E30:H30)*$P$8/$P$92 -> 31.643532 | Q30: =SUM(O30:P30) -> 363.50677 | R30: =Q30-N30 -> 256.54177 | S30: =$S$8 -> 2336.4 | T30: =R30*S30 -> 599384.2
D31: Cơ công | F31: 5 | G31: 1 | I31: =E31*115+F31*38+G31*28+H31*11 -> 218 | J31: =SUM(E31:H31)*6.3 -> 37.8 | K31: =(I31+J31)*5% -> 12.79 | L31: =(I31+J31)*10% -> 25.58 | M31: =SUM(E31:H31)*2 -> 12 | N31: =I31+J31-K31-L31-M31 -> 205.43 | O31: =Sheet1!I42 -> 368.38907 | P31: =SUM(E31:H31)*$P$8/$P$92 -> 63.287064 | Q31: =SUM(O31:P31) -> 431.67614 | R31: =Q31-N31 -> 226.24614 | S31: =$S$8 -> 2336.4 | T31: =R31*S31 -> 528601.47 | U31: =T31 -> 528601.47 | V31: Vũ Quang Trung
B32: 11 | C32: Ban tài chính | D32: TB Thịnh | F32: 1 | I32: =E32*115+F32*38+G32*28+H32*11 -> 38 | J32: =SUM(E32:H32)*6.3 -> 6.3 | K32: =(I32+J32)*5% -> 2.215 | L32: =(I32+J32)*10% -> 4.43 | M32: =SUM(E32:H32)*2 -> 2 | N32: =I32+J32-K32-L32-M32 -> 35.655 | O32: =Sheet1!I44 -> 384.043 | P32: =SUM(E32:H32)*$P$8/$P$92 -> 10.547844 | Q32: =SUM(O32:P32) -> 394.59084 | R32: =Q32-N32 -> 358.93584 | S32: =$S$8 -> 2336.4 | T32: =R32*S32 -> 838617.7 | U32: =T32+T33+T34+T35 -> 2907029.6 | V32: Vũ Tuấn Thịnh
D33: P2 Việt; Thắng | F33: 2 | I33: =E33*115+F33*38+G33*28+H33*11 -> 76 | J33: =SUM(E33:H33)*6.3 -> 12.6 | K33: =(I33+J33)*5% -> 4.43 | L33: =(I33+J33)*10% -> 8.86 | M33: =SUM(E33:H33)*2 -> 4 | N33: =I33+J33-K33-L33-M33 -> 71.31 | O33: =Sheet1!I45 -> 265.07316 | P33: =SUM(E33:H33)*$P$8/$P$92 -> 21.095688 | Q33: =SUM(O33:P33) -> 286.16884 | R33: =Q33-N33 -> 214.85884 | S33: =$S$8 -> 2336.4 | T33: =R33*S33 -> 501996.2
D34: P3 Phong; Thắng | G34: 3 | I34: =E34*115+F34*38+G34*28+H34*11 -> 84 | J34: =SUM(E34:H34)*6.3 -> 18.9 | K34: =(I34+J34)*5% -> 5.145 | L34: =(I34+J34)*10% -> 10.29 | M34: =SUM(E34:H34)*2 -> 6 | N34: =I34+J34-K34-L34-M34 -> 81.465 | O34: =Sheet1!I46 -> 566.67214 | P34: =SUM(E34:H34)*$P$8/$P$92 -> 31.643532 | Q34: =SUM(O34:P34) -> 598.31567 | R34: =Q34-N34 -> 516.85067 | S34: =$S$8 -> 2336.4 | T34: =R34*S34 -> 1207569.9
D35: P4 Vũ;Giang | G35: 2 | I35: =E35*115+F35*38+G35*28+H35*11 -> 56 | J35: =SUM(E35:H35)*6.3 -> 12.6 | K35: =(I35+J35)*5% -> 3.43 | L35: =(I35+J35)*10% -> 6.86 | M35: =SUM(E35:H35)*2 -> 4 | N35: =I35+J35-K35-L35-M35 -> 54.31 | O35: =Sheet1!I47 -> 186.80352 | P35: =SUM(E35:H35)*$P$8/$P$92 -> 21.095688 | Q35: =SUM(O35:P35) -> 207.89921 | R35: =Q35-N35 -> 153.58921 | S35: =$S$8 -> 2336.4 | T35: =R35*S35 -> 358845.83
B36: 12 | C36: Ban cơ yếu | D36: TB Vũ | F36: 2 | I36: =E36*115+F36*38+G36*28+H36*11 -> 76 | J36: =SUM(E36:H36)*6.3 -> 12.6 | K36: =(I36+J36)*5% -> 4.43 | L36: =(I36+J36)*10% -> 8.86 | M36: =SUM(E36:H36)*2 -> 4 | N36: =I36+J36-K36-L36-M36 -> 71.31 | O36: =Sheet1!I48 -> 91.836369 | P36: =SUM(E36:H36)*$P$8/$P$92 -> 21.095688 | Q36: =SUM(O36:P36) -> 112.93206 | R36: =Q36-N36 -> 41.622057 | S36: =$S$8 -> 2336.4 | T36: =R36*S36 -> 97245.774 | U36: =T36+T37 -> 182158.05 | V36: Vũ Văn Miện
D37: TL Sơn; Hà; Anh | F37: 3 | I37: =E37*115+F37*38+G37*28+H37*11 -> 114 | J37: =SUM(E37:H37)*6.3 -> 18.9 | K37: =(I37+J37)*5% -> 6.645 | L37: =(I37+J37)*10% -> 13.29 | M37: =SUM(E37:H37)*2 -> 6 | N37: =I37+J37-K37-L37-M37 -> 106.965 | O37: =Sheet1!I49 -> 111.66468 | P37: =SUM(E37:H37)*$P$8/$P$92 -> 31.643532 | Q37: =SUM(O37:P37) -> 143.30821 | R37: =Q37-N37 -> 36.343208 | S37: =$S$8 -> 2336.4 | T37: =R37*S37 -> 84912.271
B38: 13 | C38: Bảo mật | F38: 4 | I38: =E38*115+F38*38+G38*28+H38*11 -> 152 | J38: =SUM(E38:H38)*6.3 -> 25.2 | K38: =(I38+J38)*5% -> 8.86 | L38: =(I38+J38)*10% -> 17.72 | M38: =SUM(E38:H38)*2 -> 8 | N38: =I38+J38-K38-L38-M38 -> 142.62 | O38: =Sheet1!I50 -> 130.44939 | P38: =SUM(E38:H38)*$P$8/$P$92 -> 42.191376 | Q38: =SUM(O38:P38) -> 172.64076 | R38: =Q38-N38 -> 30.020764 | S38: =$S$8 -> 2336.4 | T38: =R38*S38 -> 70140.512 | U38: =T38 -> 70140.512 | V38: Nguyễn Đức Đến
B39: 14 | C39: Viết Sử | F39: 1 | I39: =E39*115+F39*38+G39*28+H39*11 -> 38 | J39: =SUM(E39:H39)*6.3 -> 6.3 | K39: =(I39+J39)*5% -> 2.215 | L39: =(I39+J39)*10% -> 4.43 | M39: =SUM(E39:H39)*2 -> 2 | N39: =I39+J39-K39-L39-M39 -> 35.655 | O39: =Sheet1!I51 -> 60.528516 | P39: =SUM(E39:H39)*$P$8/$P$92 -> 10.547844 | Q39: =SUM(O39:P39) -> 71.07636 | R39: =Q39-N39 -> 35.42136 | S39: =$S$8 -> 2336.4 | T39: =R39*S39 -> 82758.465 | U39: =T39 -> 82758.465 | V39: Phạm Duy Hiển
B40: 15 | C40: Trợ lý chính trị | F40: 1 | H40: 1 | I40: =E40*115+F40*38+G40*28+H40*11 -> 49 | J40: =SUM(E40:H40)*6.3 -> 12.6 | K40: =(I40+J40)*5% -> 3.08 | L40: =(I40+J40)*10% -> 6.16 | M40: =SUM(E40:H40)*2 -> 4 | N40: =I40+J40-K40-L40-M40 -> 48.36 | O40: =Sheet1!I52 -> 48.005375 | P40: =SUM(E40:H40)*$P$8/$P$92 -> 21.095688 | Q40: =SUM(O40:P40) -> 69.101063 | R40: =Q40-N40 -> 20.741063 | S40: =$S$8 -> 2336.4 | T40: =R40*S40 -> 48459.419 | U40: =T40 -> 48459.419 | V40: Phạm Bằng Thương
B41: 16 | C41: Tổ xe | F41: 5 | G41: 12 | I41: =E41*115+F41*38+G41*28+H41*11 -> 526 | J41: =SUM(E41:H41)*6.3 -> 107.1 | K41: =(I41+J41)*5% -> 31.655 | L41: =(I41+J41)*10% -> 63.31 | M41: =SUM(E41:H41)*2 -> 34 | N41: =I41+J41-K41-L41-M41 -> 504.135 | O41: =SUM(Sheet1!I53:I56) -> 672.07525 | P41: =SUM(E41:H41)*$P$8/$P$92 -> 179.31335 | Q41: =SUM(O41:P41) -> 851.38859 | R41: =Q41-N41 -> 347.25359 | S41: =$S$8 -> 2336.4 | T41: =R41*S41 -> 811323.3 | U41: =T41 -> 811323.3 | V41: Nguyễn Khắc Côn
B42: 17 | C42: Bảo đảm (Không tính quân y f bộ) | E42: 1 | F42: 6 | H42: 26 | I42: =E42*115+F42*38+G42*28+H42*11 -> 629 | J42: =SUM(E42:H42)*6.3 -> 207.9 | K42: =(I42+J42)*5% -> 41.845 | L42: =(I42+J42)*10% -> 83.69 | M42: =-(SUM(M10:M41)+SUM(M45:M61)+SUM(M63:M92)) -> -296 | N42: =I42+J42-K42-L42-M42 -> 1007.365 | O42: =SUM(Sheet1!I100:I105) -> 1540.3464 | P42: =SUM(E42:H42)*$P$8/$P$92 -> 348.07885 | Q42: =SUM(O42:P42) -> 1888.4252 | R42: =Q42-N42 -> 881.06022 | S42: =$S$8 -> 2336.4 | T42: =R42*S42 -> 2058509.1 | U42: =T42 -> 2058509.1 | V42: Hồ Sỹ Hùng
B43: 18 | C43: Phòng cắt tóc | I43: =E43*115+F43*38+G43*28+H43*11 -> 0 | J43: =SUM(E43:H43)*6.3 -> 0 | K43: =(I43+J43)*5% -> 0 | L43: =(I43+J43)*10% -> 0 | N43: =I43+J43-K43-L43-M43 -> 0 | O43: =Sheet1!I137 -> 91.836369 | P43: =SUM(E43:H43)*$P$8/$P$92 -> 0 | Q43: =SUM(O43:P43) -> 91.836369 | R43: =Q43-N43 -> 91.836369 | S43: =$S$8 -> 2336.4 | T43: =R43*S43 -> 214566.49 | U43: =T43 -> 214566.49 | V43: Hồ Sỹ Hùng
...
